Workbook
Name RankingFundamentalWeight: Settings!$C$65
Name RankingSentimentWeight: Settings!$C$66

Sheet README
A1: KADIOKO DSE SHEET
A2: Created by GODFREY MARIKI · NECUVA GROUP
A3: Kadioko DSE Sheet · workbook name, authorship and this README are locked. All analytical sheets are protected; the data-entry and Settings cells remain open for everyday use.
A4: START HERE ▸ open the 'How To Read' sheet (second tab). It explains, in five steps, how to check the data, how the Market Pressure Score is built from its six components, exactly what each Signal does and does not mean, and the three confirmations to run before you rely on any score.
A5: A daily market-analysis workbook for the Dar es Salaam Stock Exchange (DSE). It stores every market observation once, in a single master table, and derives every summary, score, report and chart from that one table. Built to run in Google Sheets, and kept compatible with Microsoft Excel 365.
A6: 1. WHAT THIS WORKBOOK IS
A7: Kadioko DSE Sheet turns raw end-of-day DSE data (price, turnover, volume, deals, outstanding bid and offer quantities, market capitalisation) into daily summaries, order-book pressure scores, momentum rankings, liquidity measures, weekly and monthly reports, and an investor dashboard.
A8: There is exactly ONE source of truth: the 'Daily Data' sheet. One row = one security on one trading date. Nothing is ever copied by hand between sheets. If a number looks wrong anywhere, it is fixed in Daily Data (or in Settings) and the whole workbook updates.
A9: 2. HOW TO ENTER OR IMPORT DATA
A10: Manual entry — type or paste raw values into Daily Data columns A to Q (Date … Validation Status). Columns R to AV are formulas and fill themselves; never type over them.
A11: CSV import — use the layout on the 'CSV Template' sheet. Column order must match exactly. Paste new rows underneath the last populated row, starting in column A.
A12: Google Apps Script — copy the code from the 'Apps Script' sheet into your Sheet's script editor. manualCsvImport() loads a CSV from Drive; importFromOfficialFeed() is the adapter for a licensed DSE data feed. Imports are idempotent: the same Symbol + Date is never inserted twice.
... A66: The Ranking sheet is colour-coded: green = strong, amber = average, red = weak, with a colour key at rows 79-81.

Sheet How To Read
A1: HOW TO READ KADIOKO DSE SHEET
A2: Created by GODFREY MARIKI · NECUVA GROUP
A3: A five-minute routine for reading the workbook correctly, and a full explanation of the Market Pressure Score and the Signal wording. Read this before you act on any number in this file.
A5: STEP 1 — CHECK THE DATA BEFORE YOU READ ANY SCORE
A6: Every score is only as good as the row it was built from. Open the Data Quality sheet and look at the three counters at the top. If ERRORS is anything other than zero, fix those rows in Daily Data first — an error means the row is structurally wrong (duplicate date, negative price, close outside the day's high/low) and the analytics built on it cannot be trusted.
A7: ="Live status: ERRORS = "&'Data Quality'!$E$2&" WARNINGS = "&'Data Quality'!$G$2&" ROWS PASSED = "&'Data Quality'!$I$2&" → "&IF('Data Quality'!$E$2>0,"DO NOT rely on the analytics until the errors are cleared.",IF('Data Quality'!$G$2>0,"Usable, but review the warnings.","Data is clean.")) -> Live status: ERRORS = 2 WARNINGS = 14 ROWS PASSED = 132 → DO NOT rely on the analytics until the errors are cleared.
A9: STEP 2 — READ THE DAY BEFORE YOU READ A COUNTER
A10: Set the date in Settings!C13, then open Daily Summary. Look at total turnover, the number of counters that actually traded, and the gainers/losers split. This is your context. A pressure score of 85 on a day when only three counters traded means far less than the same score on a busy day.
A11: Then open Market Sentiment. It lists every security in the Symbols master for that one date, side by side.
A13: STEP 3 — THE MARKET PRESSURE SCORE (0–100)
A14: The Market Pressure Score answers exactly one question: at the close, was the resting order book leaning toward the buy side or the sell side, and was that lean confirmed by price and volume? It is a measure of PRESSURE. It is not a forecast, and it is not advice.
A15: 0 = extreme sell-side pressure · 50 = balanced · 100 = extreme buy-side pressure
A17: Score band | B17: Signal shown | C17: What it means | D17: What it does NOT mean
A18: 0 – 19 | B18: Extreme Sell Pressure | C18: The offer side of the book overwhelms the bid side, and price/volume confirm the downward lean. | D18: It does not mean 'sell now'. Heavy offers can be one large seller working an order, and can clear in a day.
A19: 20 – 39 | B19: Sell Pressure | C19: More shares queued to sell than to buy; the lean is real but not extreme. | D19: It does not mean the price will fall.
A20: 40 – 60 | B20: Neutral | C20: Bid and offer are roughly balanced, or the signals disagree with each other. | D20: It does not mean 'nothing is happening' — check volume and momentum separately.
A21: 61 – 80 | B21: Buy Pressure | C21: More shares queued to buy than to sell; demand is leaning positive. | D21: It does not mean 'buy'.
A22: 81 – 100 | B22: Extreme Buy Pressure | C22: The bid side overwhelms the offer side, confirmed by price and volume. | D22: It does NOT mean 'strong buy'. A thin offer side can simply mean nobody is willing to sell at that price yet.
A24: HOW THE SIGNAL IS PRODUCED — THE FULL CHAIN
A25: Six component scores are calculated separately, each on its own 0–100 scale, in Daily Data columns AO to AT. They are then blended using the weights in Settings!C32:C37 to give the Market Pressure Score in column AH. The Signal in column AJ is nothing more than the score compared with the four thresholds in Settings!C46:C49. Nothing is hidden: you can click any component and read its formula.
A26: Component (column) | B26: Default weight | C26: The question it answers | D26: Where to see it
A27: P1 Order-book position (AO) | B27: 0.3 | C27: How far from balance is the bid/offer ratio right now? | D27: Daily Data column S (B/O Ratio)
A28: P2 B/O momentum (AP) | B28: 0.2 | C28: Is that imbalance building or fading versus its own recent average? | D28: Daily Data column AA (B/O Momentum %)
A29: P3 Price momentum (AQ) | B29: 0.15 | C29: Did the price actually move in the same direction? | D29: Daily Data column H (Change %)
A30: P4 Volume confirmation (AR) | B30: 0.15 | C30: Was the move backed by heavier-than-normal trading? | D30: Daily Data column AC (Volume Ratio)
A31: P5 Book depth vs market cap (AS) | B31: 0.1 | C31: Is the imbalance big relative to the size of the company? | D31: Daily Data columns V and W
A32: P6 Liquidity adjustment (AT) | B32: 0.1 | C32: Is this counter liquid enough for the reading to mean anything? Illiquid names are pulled back toward 50. | D32: Daily Data column AG (Liquidity Score)
A34: STEP 4 — WORKED EXAMPLE, CALCULATED LIVE
A35: ="This example follows the security selected in Settings!C14 ("&Settings!$C$14&") on "&TEXT(Settings!$C$13,"yyyy-mm-dd")&". Change either setting and the numbers below recalculate." -> This example follows the security selected in Settings!C14 (CRDB) on 2026-08-14. Change either setting and the numbers below recalculate.
A36: Component | B36: Score (0–100) | C36: Weight | D36: Weighted contribution
A37: P1 Order-book position | B37: =IFERROR(INDEX('Daily Data'!$AO$4:$AO$503,MATCH(Settings!$C$14&"|"&TEXT(Settings!$C$13,"yyyy-mm-dd"),'Daily Data'!$AU$4:$AU$503,0)),"no data") -> 100 | C37: =Settings!$C$32 -> 0.3 | D37: =IF(NOT(ISNUMBER($B37)),"",$B37*$C37) -> 30
A38: P2 B/O momentum | B38: =IFERROR(INDEX('Daily Data'!$AP$4:$AP$503,MATCH(Settings!$C$14&"|"&TEXT(Settings!$C$13,"yyyy-mm-dd"),'Daily Data'!$AU$4:$AU$503,0)),"no data") -> 50 | C38: =Settings!$C$33 -> 0.2 | D38: =IF(NOT(ISNUMBER($B38)),"",$B38*$C38) -> 10
A39: P3 Price momentum | B39: =IFERROR(INDEX('Daily Data'!$AQ$4:$AQ$503,MATCH(Settings!$C$14&"|"&TEXT(Settings!$C$13,"yyyy-mm-dd"),'Daily Data'!$AU$4:$AU$503,0)),"no data") -> 50 | C39: =Settings!$C$34 -> 0.15 | D39: =IF(NOT(ISNUMBER($B39)),"",$B39*$C39) -> 7.5
A40: P4 Volume confirmation | B40: =IFERROR(INDEX('Daily Data'!$AR$4:$AR$503,MATCH(Settings!$C$14&"|"&TEXT(Settings!$C$13,"yyyy-mm-dd"),'Daily Data'!$AU$4:$AU$503,0)),"no data") -> 50 | C40: =Settings!$C$35 -> 0.15 | D40: =IF(NOT(ISNUMBER($B40)),"",$B40*$C40) -> 7.5
A41: P5 Book depth vs market cap | B41: =IFERROR(INDEX('Daily Data'!$AS$4:$AS$503,MATCH(Settings!$C$14&"|"&TEXT(Settings!$C$13,"yyyy-mm-dd"),'Daily Data'!$AU$4:$AU$503,0)),"no data") -> 60.084588 | C41: =Settings!$C$36 -> 0.1 | D41: =IF(NOT(ISNUMBER($B41)),"",$B41*$C41) -> 6.0084588
A42: P6 Liquidity adjustment | B42: =IFERROR(INDEX('Daily Data'!$AT$4:$AT$503,MATCH(Settings!$C$14&"|"&TEXT(Settings!$C$13,"yyyy-mm-dd"),'Daily Data'!$AU$4:$AU$503,0)),"no data") -> 96.35 | C42: =Settings!$C$37 -> 0.1 | D42: =IF(NOT(ISNUMBER($B42)),"",$B42*$C42) -> 9.635
A43: MARKET PRESSURE SCORE = sum of contributions ÷ sum of weights | C43: =SUM($C$37:$C$42) -> 1 | D43: =IFERROR(ROUND(SUM($D$37:$D$42)/SUM($C$37:$C$42),1),"no data") -> 70.6
A44: SIGNAL SHOWN (from Settings!C46:C49) | D44: =IFERROR(INDEX('Daily Data'!$AJ$4:$AJ$503,MATCH(Settings!$C$14&"|"&TEXT(Settings!$C$13,"yyyy-mm-dd"),'Daily Data'!$AU$4:$AU$503,0)),"no data") -> Buy Pressure
A45: DATA CONFIDENCE FOR THIS ROW (trust the score only above Settings!C57) | D45: =IFERROR(INDEX('Daily Data'!$AI$4:$AI$503,MATCH(Settings!$C$14&"|"&TEXT(Settings!$C$13,"yyyy-mm-dd"),'Daily Data'!$AU$4:$AU$503,0)),"no data") -> 75
A47: STEP 5 — THREE CONFIRMATIONS BEFORE THE SCORE MEANS ANYTHING
...

Sheet Settings
A1: 0.03
A2: Settings — all model assumptions are configurable here. Amber cells are user inputs; grey cells are calculated.
B3: Setting | C3: Value | D3: Notes / Description
B4: IDENTITY & OPERATIONS
B5: Workbook Name (locked) | C5: Kadioko DSE Sheet | D5: Locked — created by Godfrey Mariki, Necuva Group
B6: Author / Owner (locked) | C6: Godfrey Mariki — Necuva Group | D6: Locked — attribution, do not edit
B7: Default Language | C7: English | D7: English or Kiswahili (report narrative)
B8: Data Source Mode | C8: Official Feed | D8: Manual CSV | Official Feed | Configured Endpoint
B9: Import Endpoint URL (optional) | D9: Used only by importFromConfiguredEndpoint()
B10: Last Import Date | C10: 46265 | D10: Written by Apps Script
B11: Last Successful Refresh | D11: Written by Apps Script
B12: SELECTIONS
B13: Selected Analysis Date | C13: 46248 | D13: Drives Daily Summary & Market Sentiment
B14: Selected Symbol | C14: CRDB | D14: Drives Stock Analyzer
B15: Comparison Symbol A | C15: CRDB | D15: Compare sheet
B16: Comparison Symbol B | C16: NMB | D16: Compare sheet
B17: Report Week Number (ISO) | C17: 33 | D17: Weekly Report
B18: Report Year | C18: 2026 | D18: Weekly & Monthly Report
B19: Report Month (1-12) | C19: 8 | D19: Monthly Report
B20: ANALYSIS WINDOWS (trading observations)
B21: Rolling B/O window | C21: 5 | D21: Default 5 prior observations
B22: Rolling volume window | C22: 20 | D22: Default 20 prior observations
B23: Momentum / price-return window | C23: 5 | D23: Used for 5D return
B24: LIQUIDITY THRESHOLDS & BENCHMARKS
B25: Minimum trading volume threshold | C25: 1000 | D25: Below this a counter is flagged Illiquid
B26: Minimum turnover threshold (TZS) | C26: 5000000 | D26: Below this a counter is flagged Illiquid
B27: Turnover benchmark = score 100 (TZS) | C27: 1000000000 | D27: Liquidity sub-score scaling
B28: Volume benchmark = score 100 (shares) | C28: 500000 | D28: Liquidity sub-score scaling
B29: Deals benchmark = score 100 | C29: 100 | D29: Liquidity sub-score scaling
B30: Minimum liquidity score to be ranked | C30: 20 | D30: Stops illiquid counters topping rankings
B31: MARKET PRESSURE MODEL WEIGHTS (must total 100%)
B32: W1 - B/O position | C32: 0.3 | D32: Order-book imbalance level
B33: W2 - B/O momentum | C33: 0.2 | D33: Change in imbalance vs rolling average
B34: W3 - Price momentum | C34: 0.15 | D34: Daily change %
B35: W4 - Volume confirmation | C35: 0.15 | D35: Does volume confirm the price move?
B36: W5 - Book depth vs market cap | C36: 0.1 | D36: Absolute size of book vs MCAP
B37: W6 - Liquidity confirmation | C37: 0.1 | D37: Damps book signal for illiquid names
B38: Total weight check | C38: =SUM(C32:C37) -> 1 | D38: Must equal 100%
B39: SCORE CALIBRATION
B40: B/O ratio cap (x) = score 100 | C40: 4 | D40: B/O of 4.0x scores 100; 0.25x scores 0 (log scale)
...

Sheet Symbols
A1: KADIOKO DSE SHEET — SECURITY MASTER
A2: Add every DSE-listed instrument you track here. All analytics work for ANY symbol in this list (rows 4-43). Shares outstanding are indicative — verify against the official DSE register before relying on market-cap figures.
A3: Symbol | B3: Company / Security Name | C3: Security Type | D3: Sector | E3: Listed | F3: Active | G3: Currency | H3: Shares Outstanding | I3: Notes | J3: Data Source Identifier | K3: Verification Status
A4: AFRIPRISE | B4: Afriprise Investment PLC | C4: Ordinary Share | D4: Investment | F4: Yes | G4: TZS | H4: =IF($A4="","",IFERROR(ROUND(SUMIFS('Daily Data'!$N$4:$N$503,'Daily Data'!$B$4:$B$503,$A4,'Daily Data'!$AK$4:$AK$503,COUNTIF('Daily Data'!$B$4:$B$503,$A4))/SUMIFS('Daily Data'!$E$4:$E$503,'Daily Data'!$B$4:$B$503,$A4,'Daily Data'!$AK$4:$AK$503,COUNTIF('Daily Data'!$B$4:$B$503,$A4)),0),"")) -> 146032000 | I4: Derived: official DSE market capitalisation ÷ closing price (Daily Market Report, 23-Feb-2026). Listing date still to be confirmed against the DSE register. | J4: AFRIPRISE | K4: =IF($A4="","",IF(OR($E4="",NOT(ISNUMBER($E4))),"VERIFY — listing date missing",IF(N($H4)<=0,"VERIFY — shares outstanding missing","Verified"))) -> VERIFY — listing date missing
A5: CRDB | B5: CRDB Bank PLC | C5: Ordinary Share | D5: Banking | F5: Yes | G5: TZS | H5: =IF($A5="","",IFERROR(ROUND(SUMIFS('Daily Data'!$N$4:$N$503,'Daily Data'!$B$4:$B$503,$A5,'Daily Data'!$AK$4:$AK$503,COUNTIF('Daily Data'!$B$4:$B$503,$A5))/SUMIFS('Daily Data'!$E$4:$E$503,'Daily Data'!$B$4:$B$503,$A5,'Daily Data'!$AK$4:$AK$503,COUNTIF('Daily Data'!$B$4:$B$503,$A5)),0),"")) -> 2611837037 | I5: Derived: official DSE market capitalisation ÷ closing price (Daily Market Report, 23-Feb-2026). Listing date still to be confirmed against the DSE register. | J5: CRDB | K5: =IF($A5="","",IF(OR($E5="",NOT(ISNUMBER($E5))),"VERIFY — listing date missing",IF(N($H5)<=0,"VERIFY — shares outstanding missing","Verified"))) -> VERIFY — listing date missing
A6: DCB | B6: DCB Commercial Bank PLC | C6: Ordinary Share | D6: Banking | F6: Yes | G6: TZS | H6: =IF($A6="","",IFERROR(ROUND(SUMIFS('Daily Data'!$N$4:$N$503,'Daily Data'!$B$4:$B$503,$A6,'Daily Data'!$AK$4:$AK$503,COUNTIF('Daily Data'!$B$4:$B$503,$A6))/SUMIFS('Daily Data'!$E$4:$E$503,'Daily Data'!$B$4:$B$503,$A6,'Daily Data'!$AK$4:$AK$503,COUNTIF('Daily Data'!$B$4:$B$503,$A6)),0),"")) -> 191591398 | I6: Derived: official DSE market capitalisation ÷ closing price (Daily Market Report, 23-Feb-2026). Listing date still to be confirmed against the DSE register. | J6: DCB | K6: =IF($A6="","",IF(OR($E6="",NOT(ISNUMBER($E6))),"VERIFY — listing date missing",IF(N($H6)<=0,"VERIFY — shares outstanding missing","Verified"))) -> VERIFY — listing date missing
A7: DSE | B7: Dar es Salaam Stock Exchange PLC | C7: Ordinary Share | D7: Financial Services | F7: Yes | G7: TZS | H7: =IF($A7="","",IFERROR(ROUND(SUMIFS('Daily Data'!$N$4:$N$503,'Daily Data'!$B$4:$B$503,$A7,'Daily Data'!$AK$4:$AK$503,COUNTIF('Daily Data'!$B$4:$B$503,$A7))/SUMIFS('Daily Data'!$E$4:$E$503,'Daily Data'!$B$4:$B$503,$A7,'Daily Data'!$AK$4:$AK$503,COUNTIF('Daily Data'!$B$4:$B$503,$A7)),0),"")) -> 23823440 | I7: Derived: official DSE market capitalisation ÷ closing price (Daily Market Report, 23-Feb-2026). Listing date still to be confirmed against the DSE register. | J7: DSE | K7: =IF($A7="","",IF(OR($E7="",NOT(ISNUMBER($E7))),"VERIFY — listing date missing",IF(N($H7)<=0,"VERIFY — shares outstanding missing","Verified"))) -> VERIFY — listing date missing
A8: EABL | B8: East African Breweries PLC | C8: Ordinary Share (cross-listed) | D8: Consumer Goods | F8: Yes | G8: TZS | H8: =IF($A8="","",IFERROR(ROUND(SUMIFS('Daily Data'!$N$4:$N$503,'Daily Data'!$B$4:$B$503,$A8,'Daily Data'!$AK$4:$AK$503,COUNTIF('Daily Data'!$B$4:$B$503,$A8))/SUMIFS('Daily Data'!$E$4:$E$503,'Daily Data'!$B$4:$B$503,$A8,'Daily Data'!$AK$4:$AK$503,COUNTIF('Daily Data'!$B$4:$B$503,$A8)),0),"")) -> 790774597 | I8: Derived: official DSE market capitalisation ÷ closing price (Daily Market Report, 23-Feb-2026). Listing date still to be confirmed against the DSE register. | J8: EABL | K8: =IF($A8="","",IF(OR($E8="",NOT(ISNUMBER($E8))),"VERIFY — listing date missing",IF(N($H8)<=0,"VERIFY — shares outstanding missing","Verified"))) -> VERIFY — listing date missing
A9: JATU | B9: JATU PLC | C9: Ordinary Share | D9: Agriculture | F9: Yes | G9: TZS | H9: =IF($A9="","",IFERROR(ROUND(SUMIFS('Daily Data'!$N$4:$N$503,'Daily Data'!$B$4:$B$503,$A9,'Daily Data'!$AK$4:$AK$503,COUNTIF('Daily Data'!$B$4:$B$503,$A9))/SUMIFS('Daily Data'!$E$4:$E$503,'Daily Data'!$B$4:$B$503,$A9,'Daily Data'!$AK$4:$AK$503,COUNTIF('Daily Data'!$B$4:$B$503,$A9)),0),"")) -> 19924528 | I9: Derived: official DSE market capitalisation ÷ closing price (Daily Market Report, 23-Feb-2026). Listing date still to be confirmed against the DSE register. | J9: JATU | K9: =IF($A9="","",IF(OR($E9="",NOT(ISNUMBER($E9))),"VERIFY — listing date missing",IF(N($H9)<=0,"VERIFY — shares outstanding missing","Verified"))) -> VERIFY — listing date missing
A10: JHL | B10: Jubilee Holdings Ltd | C10: Ordinary Share (cross-listed) | D10: Insurance | F10: Yes | G10: TZS | H10: =IF($A10="","",IFERROR(ROUND(SUMIFS('Daily Data'!$N$4:$N$503,'Daily Data'!$B$4:$B$503,$A10,'Daily Data'!$AK$4:$AK$503,COUNTIF('Daily Data'!$B$4:$B$503,$A10))/SUMIFS('Daily Data'!$E$4:$E$503,'Daily Data'!$B$4:$B$503,$A10,'Daily Data'!$AK$4:$AK$503,COUNTIF('Daily Data'!$B$4:$B$503,$A10)),0),"")) -> 72472832 | I10: Derived: official DSE market capitalisation ÷ closing price (Daily Market Report, 23-Feb-2026). Listing date still to be confirmed against the DSE register. | J10: JHL | K10: =IF($A10="","",IF(OR($E10="",NOT(ISNUMBER($E10))),"VERIFY — listing date missing",IF(N($H10)<=0,"VERIFY — shares outstanding missing","Verified"))) -> VERIFY — listing date missing
A11: KA | B11: Kenya Airways PLC | C11: Ordinary Share (cross-listed) | D11: Transport | F11: Yes | G11: TZS | H11: =IF($A11="","",IFERROR(ROUND(SUMIFS('Daily Data'!$N$4:$N$503,'Daily Data'!$B$4:$B$503,$A11,'Daily Data'!$AK$4:$AK$503,COUNTIF('Daily Data'!$B$4:$B$503,$A11))/SUMIFS('Daily Data'!$E$4:$E$503,'Daily Data'!$B$4:$B$503,$A11,'Daily Data'!$AK$4:$AK$503,COUNTIF('Daily Data'!$B$4:$B$503,$A11)),0),"")) -> 5681454545 | I11: Derived: official DSE market capitalisation ÷ closing price (Daily Market Report, 23-Feb-2026). Listing date still to be confirmed against the DSE register. | J11: KA | K11: =IF($A11="","",IF(OR($E11="",NOT(ISNUMBER($E11))),"VERIFY — listing date missing",IF(N($H11)<=0,"VERIFY — shares outstanding missing","Verified"))) -> VERIFY — listing date missing
A12: KCB | B12: KCB Group PLC | C12: Ordinary Share (cross-listed) | D12: Banking | F12: Yes | G12: TZS | H12: =IF($A12="","",IFERROR(ROUND(SUMIFS('Daily Data'!$N$4:$N$503,'Daily Data'!$B$4:$B$503,$A12,'Daily Data'!$AK$4:$AK$503,COUNTIF('Daily Data'!$B$4:$B$503,$A12))/SUMIFS('Daily Data'!$E$4:$E$503,'Daily Data'!$B$4:$B$503,$A12,'Daily Data'!$AK$4:$AK$503,COUNTIF('Daily Data'!$B$4:$B$503,$A12)),0),"")) -> 2970338462 | I12: Derived: official DSE market capitalisation ÷ closing price (Daily Market Report, 23-Feb-2026). Listing date still to be confirmed against the DSE register. | J12: KCB | K12: =IF($A12="","",IF(OR($E12="",NOT(ISNUMBER($E12))),"VERIFY — listing date missing",IF(N($H12)<=0,"VERIFY — shares outstanding missing","Verified"))) -> VERIFY — listing date missing
A13: MBP | B13: Maendeleo Bank PLC | C13: Ordinary Share | D13: Banking | F13: Yes | G13: TZS | H13: =IF($A13="","",IFERROR(ROUND(SUMIFS('Daily Data'!$N$4:$N$503,'Daily Data'!$B$4:$B$503,$A13,'Daily Data'!$AK$4:$AK$503,COUNTIF('Daily Data'!$B$4:$B$503,$A13))/SUMIFS('Daily Data'!$E$4:$E$503,'Daily Data'!$B$4:$B$503,$A13,'Daily Data'!$AK$4:$AK$503,COUNTIF('Daily Data'!$B$4:$B$503,$A13)),0),"")) -> 29988095 | I13: Derived: official DSE market capitalisation ÷ closing price (Daily Market Report, 23-Feb-2026). Listing date still to be confirmed against the DSE register. | J13: MBP | K13: =IF($A13="","",IF(OR($E13="",NOT(ISNUMBER($E13))),"VERIFY — listing date missing",IF(N($H13)<=0,"VERIFY — shares outstanding missing","Verified"))) -> VERIFY — listing date missing
A14: MCB | B14: MCB — name to confirm with DSE | C14: Ordinary Share | D14: Banking | F14: Yes | G14: TZS | H14: =IF($A14="","",IFERROR(ROUND(SUMIFS('Daily Data'!$N$4:$N$503,'Daily Data'!$B$4:$B$503,$A14,'Daily Data'!$AK$4:$AK$503,COUNTIF('Daily Data'!$B$4:$B$503,$A14))/SUMIFS('Daily Data'!$E$4:$E$503,'Daily Data'!$B$4:$B$503,$A14,'Daily Data'!$AK$4:$AK$503,COUNTIF('Daily Data'!$B$4:$B$503,$A14)),0),"")) -> 247308642 | I14: Derived: official DSE market capitalisation ÷ closing price (Daily Market Report, 23-Feb-2026). Listing date still to be confirmed against the DSE register. | J14: MCB | K14: =IF($A14="","",IF(OR($E14="",NOT(ISNUMBER($E14))),"VERIFY — listing date missing",IF(N($H14)<=0,"VERIFY — shares outstanding missing","Verified"))) -> VERIFY — listing date missing
A15: MKCB | B15: Mkombozi Commercial Bank PLC | C15: Ordinary Share | D15: Banking | F15: Yes | G15: TZS | H15: =IF($A15="","",IFERROR(ROUND(SUMIFS('Daily Data'!$N$4:$N$503,'Daily Data'!$B$4:$B$503,$A15,'Daily Data'!$AK$4:$AK$503,COUNTIF('Daily Data'!$B$4:$B$503,$A15))/SUMIFS('Daily Data'!$E$4:$E$503,'Daily Data'!$B$4:$B$503,$A15,'Daily Data'!$AK$4:$AK$503,COUNTIF('Daily Data'!$B$4:$B$503,$A15)),0),"")) -> 23555851 | I15: Derived: official DSE market capitalisation ÷ closing price (Daily Market Report, 23-Feb-2026). Listing date still to be confirmed against the DSE register. | J15: MKCB | K15: =IF($A15="","",IF(OR($E15="",NOT(ISNUMBER($E15))),"VERIFY — listing date missing",IF(N($H15)<=0,"VERIFY — shares outstanding missing","Verified"))) -> VERIFY — listing date missing
... A33: VERTEX-ETF | B33: VERTEX ETF | C33: ETF | D33: Exchange Traded Fund | F33: Yes | G33: TZS | H33: =IF($A33="","",IFERROR(ROUND(SUMIFS('Daily Data'!$N$4:$N$503,'Daily Data'!$B$4:$B$503,$A33,'Daily Data'!$AK$4:$AK$503,COUNTIF('Daily Data'!$B$4:$B$503,$A33))/SUMIFS('Daily Data'!$E$4:$E$503,'Daily Data'!$B$4:$B$503,$A33,'Daily Data'!$AK$4:$AK$503,COUNTIF('Daily Data'!$B$4:$B$503,$A33)),0),"")) -> 54000000 | I33: Derived: official DSE market capitalisation ÷ closing price (Daily Market Report, 23-Feb-2026). Listing date still to be confirmed against the DSE register. | J33: VERTEX-ETF | K33: =IF($A33="","",IF(OR($E33="",NOT(ISNUMBER($E33))),"VERIFY — listing date missing",IF(N($H33)<=0,"VERIFY — shares outstanding missing","Verified"))) -> VERIFY — listing date missing
K34: =IF($A34="","",IF(OR($E34="",NOT(ISNUMBER($E34))),"VERIFY — listing date missing",IF(N($H34)<=0,"VERIFY — shares outstanding missing","Verified")))
K35: =IF($A35="","",IF(OR($E35="",NOT(ISNUMBER($E35))),"VERIFY — listing date missing",IF(N($H35)<=0,"VERIFY — shares outstanding missing","Verified")))
K36: =IF($A36="","",IF(OR($E36="",NOT(ISNUMBER($E36))),"VERIFY — listing date missing",IF(N($H36)<=0,"VERIFY — shares outstanding missing","Verified")))
K37: =IF($A37="","",IF(OR($E37="",NOT(ISNUMBER($E37))),"VERIFY — listing date missing",IF(N($H37)<=0,"VERIFY — shares outstanding missing","Verified")))
K38: =IF($A38="","",IF(OR($E38="",NOT(ISNUMBER($E38))),"VERIFY — listing date missing",IF(N($H38)<=0,"VERIFY — shares outstanding missing","Verified")))
K39: =IF($A39="","",IF(OR($E39="",NOT(ISNUMBER($E39))),"VERIFY — listing date missing",IF(N($H39)<=0,"VERIFY — shares outstanding missing","Verified")))
K40: =IF($A40="","",IF(OR($E40="",NOT(ISNUMBER($E40))),"VERIFY — listing date missing",IF(N($H40)<=0,"VERIFY — shares outstanding missing","Verified")))
K41: =IF($A41="","",IF(OR($E41="",NOT(ISNUMBER($E41))),"VERIFY — listing date missing",IF(N($H41)<=0,"VERIFY — shares outstanding missing","Verified")))
K42: =IF($A42="","",IF(OR($E42="",NOT(ISNUMBER($E42))),"VERIFY — listing date missing",IF(N($H42)<=0,"VERIFY — shares outstanding missing","Verified")))
K43: =IF($A43="","",IF(OR($E43="",NOT(ISNUMBER($E43))),"VERIFY — listing date missing",IF(N($H43)<=0,"VERIFY — shares outstanding missing","Verified")))

Sheet Daily Data
A1: KADIOKO DSE SHEET — DAILY DATA (MASTER OBSERVATION TABLE) | E1: =IF(COUNTIF($O$4:$O$503,"Sample Fixture")>0,"⚠ SAMPLE FIXTURE ROWS PRESENT: "&COUNTIF($O$4:$O$503,"Sample Fixture")&" — run clearSampleFixtures() from the Kadioko menu, or delete them, before using this workbook on live data.","✔ No sample fixture rows — live data only.") -> ✔ No sample fixture rows — live data only.
A2: MASTER DATA TABLE — one row = one security on one trading date. Columns A–Q are raw data; R–AV are calculated. || SOURCE: Dar es Salaam Stock Exchange, Official Daily Market Reports for 10, 11, 12, 13 and 14 August 2026 (Equity Daily Prices + ETF Daily Prices), retrieved from https://dse.co.tz/ on 15 August 2026. Previous Close is carried from the prior trading day's official close within this loaded set; it is blank for each security's first day.
A3: Date | B3: Symbol | C3: Open | D3: Previous Close | E3: Close | F3: High | G3: Low | H3: Change % | I3: Turnover TZS | J3: Deals | K3: Volume | L3: Outstanding Bid Qty | M3: Outstanding Offer Qty | N3: Market Cap TZS | O3: Source | P3: Imported At | Q3: Import Run ID | R3: Validation Status | S3: B/O Ratio | T3: Bid Value | U3: Offer Value | V3: Bid % of MCAP | W3: Offer % of MCAP | X3: Average Trade Volume | Y3: Average Deal Value | Z3: 5D Average B/O | AA3: B/O Momentum % | AB3: 20D Average Volume | AC3: Volume Ratio | AD3: 5D Price Return | AE3: 20D Price Return | AF3: Daily Range % | AG3: Liquidity Score | AH3: Market Pressure Score | AI3: Data Confidence Score | AJ3: Signal | AK3: Obs Index | AL3: Year | AM3: ISO Week | AN3: Month | AO3: P1 B/O Position | AP3: P2 B/O Momentum | AQ3: P3 Price Momentum | AR3: P4 Volume Confirm | AS3: P5 Book Depth/MCAP | AT3: P6 Liquidity Confirm | AU3: Row Key | AV3: New Date Flag
A4: 46244 | B4: AFRIPRISE | C4: 640 | E4: 635 | F4: 645 | G4: 630 | H4: =IF($B4="","",IFERROR($E4/$D4-1,"")) | I4: 32583365 | J4: 207 | K4: 51224 | L4: 14378 | M4: 21492 | N4: 92730000000 | O4: DSE Official Daily Market Report | P4: 46265 | Q4: DSE-202608-10to13 | R4: {=IF($B4="","",IFERROR(IF(INDEX('Data Quality'!$U$4:$U$503,ROW()-3)=0,"PENDING",INDEX('Data Quality'!$U$4:$U$503,ROW()-3)),"PENDING"))} -> PASS | S4: =IF($B4="","",IF(N($M4)>0,$L4/$M4,"")) -> 0.66899311 | T4: =IF($B4="","",$L4*$E4) -> 9130030 | U4: =IF($B4="","",$M4*$E4) -> 13647420 | V4: =IF($B4="","",IF(N($N4)>0,$T4/$N4,"")) -> 9.8458212e-05 | W4: =IF($B4="","",IF(N($N4)>0,$U4/$N4,"")) -> 0.00014717373 | X4: =IF($B4="","",IF(N($J4)>0,$K4/$J4,"")) -> 247.45894 | Y4: =IF($B4="","",IF(N($J4)>0,$I4/$J4,"")) -> 157407.56 | Z4: =IF($B4="","",IF($AK4<=Settings!$C$21,"",IFERROR(AVERAGEIFS($S$4:$S$503,$B$4:$B$503,$B4,$AK$4:$AK$503,">="&$AK4-Settings!$C$21,$AK$4:$AK$503,"<="&$AK4-1),""))) | AA4: =IF(OR($S4="",$Z4="",N($Z4)=0),"",$S4/$Z4-1) | AB4: =IF($B4="","",IF($AK4<=Settings!$C$22,"",IFERROR(AVERAGEIFS($K$4:$K$503,$B$4:$B$503,$B4,$AK$4:$AK$503,">="&$AK4-Settings!$C$22,$AK$4:$AK$503,"<="&$AK4-1),""))) | AC4: =IF(OR($AB4="",N($AB4)=0),"",$K4/$AB4) | AD4: =IF($B4="","",IF($AK4<=Settings!$C$23,"",IFERROR($E4/SUMIFS($E$4:$E$503,$B$4:$B$503,$B4,$AK$4:$AK$503,$AK4-Settings!$C$23)-1,""))) | AE4: =IF($B4="","",IF($AK4<=Settings!$C$22,"",IFERROR($E4/SUMIFS($E$4:$E$503,$B$4:$B$503,$B4,$AK$4:$AK$503,$AK4-Settings!$C$22)-1,""))) | AF4: =IF($B4="","",IF(N($E4)>0,($F4-$G4)/$E4,"")) -> 0.023622047 | AG4: =IF($B4="","",ROUND((MIN(100,100*N($I4)/Settings!$C$27)+MIN(100,100*N($K4)/Settings!$C$28)+MIN(100,100*N($J4)/Settings!$C$29))/3,1)) -> 37.8 | AH4: =IF($B4="","",IF(SUM(Settings!$C$32:$C$37)=0,"",ROUND((Settings!$C$32*$AO4+Settings!$C$33*$AP4+Settings!$C$34*$AQ4+Settings!$C$35*$AR4+Settings!$C$36*$AS4+Settings!$C$37*$AT4)/SUM(Settings!$C$32:$C$37),1))) -> 44.6 | AI4: =IF($B4="","",MAX(0,100-IF(N($N4)>0,0,20)-IF(AND(N($L4)=0,N($M4)=0),15,0)-IF(N($J4)>0,0,10)-IF(N($K4)>0,0,10)-IF($Z4<>"",0,15)-IF($AB4<>"",0,10)-IF($R4="ERROR",20,IF($R4="WARNING",10,0)))) -> 75 | AJ4: =IF($AH4="","",IF($AH4<Settings!$C$46,"Extreme Sell Pressure",IF($AH4<Settings!$C$47,"Sell Pressure",IF($AH4<=Settings!$C$48,"Neutral",IF($AH4<=Settings!$C$49,"Buy Pressure","Extreme Buy Pressure"))))) -> Neutral | AK4: =IF($B4="","",COUNTIFS($B$4:$B$503,$B4,$A$4:$A$503,"<="&$A4)) -> 1 | AL4: =IF($A4="","",YEAR($A4)) -> 2026 | AM4: =IF($A4="","",_xlfn.ISOWEEKNUM($A4)) -> 33 | AN4: =IF($A4="","",MONTH($A4)) -> 8 | AO4: =IF($B4="","",IF(AND(N($L4)=0,N($M4)=0),50,IF(N($M4)=0,100,IF(N($L4)=0,0,MEDIAN(0,100,50+50*LN($S4)/LN(Settings!$C$40)))))) -> 35.501582 | AP4: =IF($AA4="",50,MEDIAN(0,100,50+$AA4*100*Settings!$C$41)) -> 50 | AQ4: =IF($H4="",50,MEDIAN(0,100,50+$H4*100*Settings!$C$42)) -> 50 | AR4: =IF(OR($AC4="",$H4=""),50,MEDIAN(0,100,50+SIGN($H4)*50*MEDIAN(0,1,($AC4-1)/Settings!$C$43))) -> 50 | AS4: =IF(OR($V4="",$W4=""),50,MEDIAN(0,100,50+50*($V4-$W4)/Settings!$C$44)) -> 45.128448 | AT4: =IF($AO4="",50,50+(N($AG4)/100)*($AO4-50)) -> 44.519598 | AU4: =IF($B4="","",$B4&"|"&TEXT($A4,"yyyy-mm-dd")) -> AFRIPRISE|2026-08-10 | AV4: =IF($A4="","",IF(COUNTIFS($A$4:$A4,$A4)=1,1,0)) -> 1
A5: 46244 | B5: CRDB | C5: 2590 | E5: 2600 | F5: 2620 | G5: 2580 | H5: =IF($B5="","",IFERROR($E5/$D5-1,"")) | I5: 7453641800 | J5: 1739 | K5: 2869227 | L5: 129405 | M5: 58236 | N5: 6790780000000 | O5: DSE Official Daily Market Report | P5: 46265 | Q5: DSE-202608-10to13 | R5: {=IF($B5="","",IFERROR(IF(INDEX('Data Quality'!$U$4:$U$503,ROW()-3)=0,"PENDING",INDEX('Data Quality'!$U$4:$U$503,ROW()-3)),"PENDING"))} -> PASS | S5: =IF($B5="","",IF(N($M5)>0,$L5/$M5,"")) -> 2.2220791 | T5: =IF($B5="","",$L5*$E5) -> 336453000 | U5: =IF($B5="","",$M5*$E5) -> 151413600 | V5: =IF($B5="","",IF(N($N5)>0,$T5/$N5,"")) -> 4.954556e-05 | W5: =IF($B5="","",IF(N($N5)>0,$U5/$N5,"")) -> 2.2296938e-05 | X5: =IF($B5="","",IF(N($J5)>0,$K5/$J5,"")) -> 1649.9293 | Y5: =IF($B5="","",IF(N($J5)>0,$I5/$J5,"")) -> 4286165.5 | Z5: =IF($B5="","",IF($AK5<=Settings!$C$21,"",IFERROR(AVERAGEIFS($S$4:$S$503,$B$4:$B$503,$B5,$AK$4:$AK$503,">="&$AK5-Settings!$C$21,$AK$4:$AK$503,"<="&$AK5-1),""))) | AA5: =IF(OR($S5="",$Z5="",N($Z5)=0),"",$S5/$Z5-1) | AB5: =IF($B5="","",IF($AK5<=Settings!$C$22,"",IFERROR(AVERAGEIFS($K$4:$K$503,$B$4:$B$503,$B5,$AK$4:$AK$503,">="&$AK5-Settings!$C$22,$AK$4:$AK$503,"<="&$AK5-1),""))) | AC5: =IF(OR($AB5="",N($AB5)=0),"",$K5/$AB5) | AD5: =IF($B5="","",IF($AK5<=Settings!$C$23,"",IFERROR($E5/SUMIFS($E$4:$E$503,$B$4:$B$503,$B5,$AK$4:$AK$503,$AK5-Settings!$C$23)-1,""))) | AE5: =IF($B5="","",IF($AK5<=Settings!$C$22,"",IFERROR($E5/SUMIFS($E$4:$E$503,$B$4:$B$503,$B5,$AK$4:$AK$503,$AK5-Settings!$C$22)-1,""))) | AF5: =IF($B5="","",IF(N($E5)>0,($F5-$G5)/$E5,"")) -> 0.015384615 | AG5: =IF($B5="","",ROUND((MIN(100,100*N($I5)/Settings!$C$27)+MIN(100,100*N($K5)/Settings!$C$28)+MIN(100,100*N($J5)/Settings!$C$29))/3,1)) -> 100 | AH5: =IF($B5="","",IF(SUM(Settings!$C$32:$C$37)=0,"",ROUND((Settings!$C$32*$AO5+Settings!$C$33*$AP5+Settings!$C$34*$AQ5+Settings!$C$35*$AR5+Settings!$C$36*$AS5+Settings!$C$37*$AT5)/SUM(Settings!$C$32:$C$37),1))) -> 61.8 | AI5: =IF($B5="","",MAX(0,100-IF(N($N5)>0,0,20)-IF(AND(N($L5)=0,N($M5)=0),15,0)-IF(N($J5)>0,0,10)-IF(N($K5)>0,0,10)-IF($Z5<>"",0,15)-IF($AB5<>"",0,10)-IF($R5="ERROR",20,IF($R5="WARNING",10,0)))) -> 75 | AJ5: =IF($AH5="","",IF($AH5<Settings!$C$46,"Extreme Sell Pressure",IF($AH5<Settings!$C$47,"Sell Pressure",IF($AH5<=Settings!$C$48,"Neutral",IF($AH5<=Settings!$C$49,"Buy Pressure","Extreme Buy Pressure"))))) -> Buy Pressure | AK5: =IF($B5="","",COUNTIFS($B$4:$B$503,$B5,$A$4:$A$503,"<="&$A5)) -> 1 | AL5: =IF($A5="","",YEAR($A5)) -> 2026 | AM5: =IF($A5="","",_xlfn.ISOWEEKNUM($A5)) -> 33 | AN5: =IF($A5="","",MONTH($A5)) -> 8 | AO5: =IF($B5="","",IF(AND(N($L5)=0,N($M5)=0),50,IF(N($M5)=0,100,IF(N($L5)=0,0,MEDIAN(0,100,50+50*LN($S5)/LN(Settings!$C$40)))))) -> 78.797755 | AP5: =IF($AA5="",50,MEDIAN(0,100,50+$AA5*100*Settings!$C$41)) -> 50 | AQ5: =IF($H5="",50,MEDIAN(0,100,50+$H5*100*Settings!$C$42)) -> 50 | AR5: =IF(OR($AC5="",$H5=""),50,MEDIAN(0,100,50+SIGN($H5)*50*MEDIAN(0,1,($AC5-1)/Settings!$C$43))) -> 50 | AS5: =IF(OR($V5="",$W5=""),50,MEDIAN(0,100,50+50*($V5-$W5)/Settings!$C$44)) -> 52.724862 | AT5: =IF($AO5="",50,50+(N($AG5)/100)*($AO5-50)) -> 78.797755 | AU5: =IF($B5="","",$B5&"|"&TEXT($A5,"yyyy-mm-dd")) -> CRDB|2026-08-10 | AV5: =IF($A5="","",IF(COUNTIFS($A$4:$A5,$A5)=1,1,0)) -> 0
A6: 46244 | B6: DCB | C6: 420 | E6: 410 | F6: 420 | G6: 390 | H6: =IF($B6="","",IFERROR($E6/$D6-1,"")) | I6: 5769690 | J6: 116 | K6: 14097 | L6: 4055 | M6: 95305 | N6: 78550000000 | O6: DSE Official Daily Market Report | P6: 46265 | Q6: DSE-202608-10to13 | R6: {=IF($B6="","",IFERROR(IF(INDEX('Data Quality'!$U$4:$U$503,ROW()-3)=0,"PENDING",INDEX('Data Quality'!$U$4:$U$503,ROW()-3)),"PENDING"))} -> PASS | S6: =IF($B6="","",IF(N($M6)>0,$L6/$M6,"")) -> 0.04254761 | T6: =IF($B6="","",$L6*$E6) -> 1662550 | U6: =IF($B6="","",$M6*$E6) -> 39075050 | V6: =IF($B6="","",IF(N($N6)>0,$T6/$N6,"")) -> 2.11655e-05 | W6: =IF($B6="","",IF(N($N6)>0,$U6/$N6,"")) -> 0.00049745449 | X6: =IF($B6="","",IF(N($J6)>0,$K6/$J6,"")) -> 121.52586 | Y6: =IF($B6="","",IF(N($J6)>0,$I6/$J6,"")) -> 49738.707 | Z6: =IF($B6="","",IF($AK6<=Settings!$C$21,"",IFERROR(AVERAGEIFS($S$4:$S$503,$B$4:$B$503,$B6,$AK$4:$AK$503,">="&$AK6-Settings!$C$21,$AK$4:$AK$503,"<="&$AK6-1),""))) | AA6: =IF(OR($S6="",$Z6="",N($Z6)=0),"",$S6/$Z6-1) | AB6: =IF($B6="","",IF($AK6<=Settings!$C$22,"",IFERROR(AVERAGEIFS($K$4:$K$503,$B$4:$B$503,$B6,$AK$4:$AK$503,">="&$AK6-Settings!$C$22,$AK$4:$AK$503,"<="&$AK6-1),""))) | AC6: =IF(OR($AB6="",N($AB6)=0),"",$K6/$AB6) | AD6: =IF($B6="","",IF($AK6<=Settings!$C$23,"",IFERROR($E6/SUMIFS($E$4:$E$503,$B$4:$B$503,$B6,$AK$4:$AK$503,$AK6-Settings!$C$23)-1,""))) | AE6: =IF($B6="","",IF($AK6<=Settings!$C$22,"",IFERROR($E6/SUMIFS($E$4:$E$503,$B$4:$B$503,$B6,$AK$4:$AK$503,$AK6-Settings!$C$22)-1,""))) | AF6: =IF($B6="","",IF(N($E6)>0,($F6-$G6)/$E6,"")) -> 0.073170732 | AG6: =IF($B6="","",ROUND((MIN(100,100*N($I6)/Settings!$C$27)+MIN(100,100*N($K6)/Settings!$C$28)+MIN(100,100*N($J6)/Settings!$C$29))/3,1)) -> 34.5 | AH6: =IF($B6="","",IF(SUM(Settings!$C$32:$C$37)=0,"",ROUND((Settings!$C$32*$AO6+Settings!$C$33*$AP6+Settings!$C$34*$AQ6+Settings!$C$35*$AR6+Settings!$C$36*$AS6+Settings!$C$37*$AT6)/SUM(Settings!$C$32:$C$37),1))) -> 28.5 | AI6: =IF($B6="","",MAX(0,100-IF(N($N6)>0,0,20)-IF(AND(N($L6)=0,N($M6)=0),15,0)-IF(N($J6)>0,0,10)-IF(N($K6)>0,0,10)-IF($Z6<>"",0,15)-IF($AB6<>"",0,10)-IF($R6="ERROR",20,IF($R6="WARNING",10,0)))) -> 75 | AJ6: =IF($AH6="","",IF($AH6<Settings!$C$46,"Extreme Sell Pressure",IF($AH6<Settings!$C$47,"Sell Pressure",IF($AH6<=Settings!$C$48,"Neutral",IF($AH6<=Settings!$C$49,"Buy Pressure","Extreme Buy Pressure"))))) -> Sell Pressure | AK6: =IF($B6="","",COUNTIFS($B$4:$B$503,$B6,$A$4:$A$503,"<="&$A6)) -> 1 | AL6: =IF($A6="","",YEAR($A6)) -> 2026 | AM6: =IF($A6="","",_xlfn.ISOWEEKNUM($A6)) -> 33 | AN6: =IF($A6="","",MONTH($A6)) -> 8 | AO6: =IF($B6="","",IF(AND(N($L6)=0,N($M6)=0),50,IF(N($M6)=0,100,IF(N($L6)=0,0,MEDIAN(0,100,50+50*LN($S6)/LN(Settings!$C$40)))))) -> 0 | AP6: =IF($AA6="",50,MEDIAN(0,100,50+$AA6*100*Settings!$C$41)) -> 50 | AQ6: =IF($H6="",50,MEDIAN(0,100,50+$H6*100*Settings!$C$42)) -> 50 | AR6: =IF(OR($AC6="",$H6=""),50,MEDIAN(0,100,50+SIGN($H6)*50*MEDIAN(0,1,($AC6-1)/Settings!$C$43))) -> 50 | AS6: =IF(OR($V6="",$W6=""),50,MEDIAN(0,100,50+50*($V6-$W6)/Settings!$C$44)) -> 2.3711012 | AT6: =IF($AO6="",50,50+(N($AG6)/100)*($AO6-50)) -> 32.75 | AU6: =IF($B6="","",$B6&"|"&TEXT($A6,"yyyy-mm-dd")) -> DCB|2026-08-10 | AV6: =IF($A6="","",IF(COUNTIFS($A$4:$A6,$A6)=1,1,0)) -> 0
A7: 46244 | B7: DSE | C7: 6580 | E7: 6450 | F7: 6580 | G7: 5760 | H7: =IF($B7="","",IFERROR($E7/$D7-1,"")) | I7: 15493780 | J7: 32 | K7: 2411 | L7: 1282 | M7: 4500 | N7: 153660000000 | O7: DSE Official Daily Market Report | P7: 46265 | Q7: DSE-202608-10to13 | R7: {=IF($B7="","",IFERROR(IF(INDEX('Data Quality'!$U$4:$U$503,ROW()-3)=0,"PENDING",INDEX('Data Quality'!$U$4:$U$503,ROW()-3)),"PENDING"))} -> PASS | S7: =IF($B7="","",IF(N($M7)>0,$L7/$M7,"")) -> 0.28488889 | T7: =IF($B7="","",$L7*$E7) -> 8268900 | U7: =IF($B7="","",$M7*$E7) -> 29025000 | V7: =IF($B7="","",IF(N($N7)>0,$T7/$N7,"")) -> 5.3812964e-05 | W7: =IF($B7="","",IF(N($N7)>0,$U7/$N7,"")) -> 0.00018889106 | X7: =IF($B7="","",IF(N($J7)>0,$K7/$J7,"")) -> 75.34375 | Y7: =IF($B7="","",IF(N($J7)>0,$I7/$J7,"")) -> 484180.62 | Z7: =IF($B7="","",IF($AK7<=Settings!$C$21,"",IFERROR(AVERAGEIFS($S$4:$S$503,$B$4:$B$503,$B7,$AK$4:$AK$503,">="&$AK7-Settings!$C$21,$AK$4:$AK$503,"<="&$AK7-1),""))) | AA7: =IF(OR($S7="",$Z7="",N($Z7)=0),"",$S7/$Z7-1) | AB7: =IF($B7="","",IF($AK7<=Settings!$C$22,"",IFERROR(AVERAGEIFS($K$4:$K$503,$B$4:$B$503,$B7,$AK$4:$AK$503,">="&$AK7-Settings!$C$22,$AK$4:$AK$503,"<="&$AK7-1),""))) | AC7: =IF(OR($AB7="",N($AB7)=0),"",$K7/$AB7) | AD7: =IF($B7="","",IF($AK7<=Settings!$C$23,"",IFERROR($E7/SUMIFS($E$4:$E$503,$B$4:$B$503,$B7,$AK$4:$AK$503,$AK7-Settings!$C$23)-1,""))) | AE7: =IF($B7="","",IF($AK7<=Settings!$C$22,"",IFERROR($E7/SUMIFS($E$4:$E$503,$B$4:$B$503,$B7,$AK$4:$AK$503,$AK7-Settings!$C$22)-1,""))) | AF7: =IF($B7="","",IF(N($E7)>0,($F7-$G7)/$E7,"")) -> 0.12713178 | AG7: =IF($B7="","",ROUND((MIN(100,100*N($I7)/Settings!$C$27)+MIN(100,100*N($K7)/Settings!$C$28)+MIN(100,100*N($J7)/Settings!$C$29))/3,1)) -> 11.3 | AH7: =IF($B7="","",IF(SUM(Settings!$C$32:$C$37)=0,"",ROUND((Settings!$C$32*$AO7+Settings!$C$33*$AP7+Settings!$C$34*$AQ7+Settings!$C$35*$AR7+Settings!$C$36*$AS7+Settings!$C$37*$AT7)/SUM(Settings!$C$32:$C$37),1))) -> 34.6 | AI7: =IF($B7="","",MAX(0,100-IF(N($N7)>0,0,20)-IF(AND(N($L7)=0,N($M7)=0),15,0)-IF(N($J7)>0,0,10)-IF(N($K7)>0,0,10)-IF($Z7<>"",0,15)-IF($AB7<>"",0,10)-IF($R7="ERROR",20,IF($R7="WARNING",10,0)))) -> 75 | AJ7: =IF($AH7="","",IF($AH7<Settings!$C$46,"Extreme Sell Pressure",IF($AH7<Settings!$C$47,"Sell Pressure",IF($AH7<=Settings!$C$48,"Neutral",IF($AH7<=Settings!$C$49,"Buy Pressure","Extreme Buy Pressure"))))) -> Sell Pressure | AK7: =IF($B7="","",COUNTIFS($B$4:$B$503,$B7,$A$4:$A$503,"<="&$A7)) -> 1 | AL7: =IF($A7="","",YEAR($A7)) -> 2026 | AM7: =IF($A7="","",_xlfn.ISOWEEKNUM($A7)) -> 33 | AN7: =IF($A7="","",MONTH($A7)) -> 8 | AO7: =IF($B7="","",IF(AND(N($L7)=0,N($M7)=0),50,IF(N($M7)=0,100,IF(N($L7)=0,0,MEDIAN(0,100,50+50*LN($S7)/LN(Settings!$C$40)))))) -> 4.7117815 | AP7: =IF($AA7="",50,MEDIAN(0,100,50+$AA7*100*Settings!$C$41)) -> 50 | AQ7: =IF($H7="",50,MEDIAN(0,100,50+$H7*100*Settings!$C$42)) -> 50 | AR7: =IF(OR($AC7="",$H7=""),50,MEDIAN(0,100,50+SIGN($H7)*50*MEDIAN(0,1,($AC7-1)/Settings!$C$43))) -> 50 | AS7: =IF(OR($V7="",$W7=""),50,MEDIAN(0,100,50+50*($V7-$W7)/Settings!$C$44)) -> 36.492191 | AT7: =IF($AO7="",50,50+(N($AG7)/100)*($AO7-50)) -> 44.882431 | AU7: =IF($B7="","",$B7&"|"&TEXT($A7,"yyyy-mm-dd")) -> DSE|2026-08-10 | AV7: =IF($A7="","",IF(COUNTIFS($A$4:$A7,$A7)=1,1,0)) -> 0
A8: 46244 | B8: EABL | C8: 5830 | E8: 5680 | H8: =IF($B8="","",IFERROR($E8/$D8-1,"")) | I8: 0 | J8: 0 | K8: 0 | L8: 20 | M8: 0 | N8: 4491600000000 | O8: DSE Official Daily Market Report | P8: 46265 | Q8: DSE-202608-10to13 | R8: {=IF($B8="","",IFERROR(IF(INDEX('Data Quality'!$U$4:$U$503,ROW()-3)=0,"PENDING",INDEX('Data Quality'!$U$4:$U$503,ROW()-3)),"PENDING"))} -> PASS | S8: =IF($B8="","",IF(N($M8)>0,$L8/$M8,"")) | T8: =IF($B8="","",$L8*$E8) -> 113600 | U8: =IF($B8="","",$M8*$E8) -> 0 | V8: =IF($B8="","",IF(N($N8)>0,$T8/$N8,"")) -> 2.5291656e-08 | W8: =IF($B8="","",IF(N($N8)>0,$U8/$N8,"")) -> 0 | X8: =IF($B8="","",IF(N($J8)>0,$K8/$J8,"")) | Y8: =IF($B8="","",IF(N($J8)>0,$I8/$J8,"")) | Z8: =IF($B8="","",IF($AK8<=Settings!$C$21,"",IFERROR(AVERAGEIFS($S$4:$S$503,$B$4:$B$503,$B8,$AK$4:$AK$503,">="&$AK8-Settings!$C$21,$AK$4:$AK$503,"<="&$AK8-1),""))) | AA8: =IF(OR($S8="",$Z8="",N($Z8)=0),"",$S8/$Z8-1) | AB8: =IF($B8="","",IF($AK8<=Settings!$C$22,"",IFERROR(AVERAGEIFS($K$4:$K$503,$B$4:$B$503,$B8,$AK$4:$AK$503,">="&$AK8-Settings!$C$22,$AK$4:$AK$503,"<="&$AK8-1),""))) | AC8: =IF(OR($AB8="",N($AB8)=0),"",$K8/$AB8) | AD8: =IF($B8="","",IF($AK8<=Settings!$C$23,"",IFERROR($E8/SUMIFS($E$4:$E$503,$B$4:$B$503,$B8,$AK$4:$AK$503,$AK8-Settings!$C$23)-1,""))) | AE8: =IF($B8="","",IF($AK8<=Settings!$C$22,"",IFERROR($E8/SUMIFS($E$4:$E$503,$B$4:$B$503,$B8,$AK$4:$AK$503,$AK8-Settings!$C$22)-1,""))) | AF8: =IF($B8="","",IF(N($E8)>0,($F8-$G8)/$E8,"")) -> 0 | AG8: =IF($B8="","",ROUND((MIN(100,100*N($I8)/Settings!$C$27)+MIN(100,100*N($K8)/Settings!$C$28)+MIN(100,100*N($J8)/Settings!$C$29))/3,1)) -> 0 | AH8: =IF($B8="","",IF(SUM(Settings!$C$32:$C$37)=0,"",ROUND((Settings!$C$32*$AO8+Settings!$C$33*$AP8+Settings!$C$34*$AQ8+Settings!$C$35*$AR8+Settings!$C$36*$AS8+Settings!$C$37*$AT8)/SUM(Settings!$C$32:$C$37),1))) -> 65 | AI8: =IF($B8="","",MAX(0,100-IF(N($N8)>0,0,20)-IF(AND(N($L8)=0,N($M8)=0),15,0)-IF(N($J8)>0,0,10)-IF(N($K8)>0,0,10)-IF($Z8<>"",0,15)-IF($AB8<>"",0,10)-IF($R8="ERROR",20,IF($R8="WARNING",10,0)))) -> 55 | AJ8: =IF($AH8="","",IF($AH8<Settings!$C$46,"Extreme Sell Pressure",IF($AH8<Settings!$C$47,"Sell Pressure",IF($AH8<=Settings!$C$48,"Neutral",IF($AH8<=Settings!$C$49,"Buy Pressure","Extreme Buy Pressure"))))) -> Buy Pressure | AK8: =IF($B8="","",COUNTIFS($B$4:$B$503,$B8,$A$4:$A$503,"<="&$A8)) -> 1 | AL8: =IF($A8="","",YEAR($A8)) -> 2026 | AM8: =IF($A8="","",_xlfn.ISOWEEKNUM($A8)) -> 33 | AN8: =IF($A8="","",MONTH($A8)) -> 8 | AO8: =IF($B8="","",IF(AND(N($L8)=0,N($M8)=0),50,IF(N($M8)=0,100,IF(N($L8)=0,0,MEDIAN(0,100,50+50*LN($S8)/LN(Settings!$C$40)))))) -> 100 | AP8: =IF($AA8="",50,MEDIAN(0,100,50+$AA8*100*Settings!$C$41)) -> 50 | AQ8: =IF($H8="",50,MEDIAN(0,100,50+$H8*100*Settings!$C$42)) -> 50 | AR8: =IF(OR($AC8="",$H8=""),50,MEDIAN(0,100,50+SIGN($H8)*50*MEDIAN(0,1,($AC8-1)/Settings!$C$43))) -> 50 | AS8: =IF(OR($V8="",$W8=""),50,MEDIAN(0,100,50+50*($V8-$W8)/Settings!$C$44)) -> 50.002529 | AT8: =IF($AO8="",50,50+(N($AG8)/100)*($AO8-50)) -> 50 | AU8: =IF($B8="","",$B8&"|"&TEXT($A8,"yyyy-mm-dd")) -> EABL|2026-08-10 | AV8: =IF($A8="","",IF(COUNTIFS($A$4:$A8,$A8)=1,1,0)) -> 0
A9: 46244 | B9: JATU | C9: 265 | E9: 265 | H9: =IF($B9="","",IFERROR($E9/$D9-1,"")) | I9: 0 | J9: 0 | K9: 0 | L9: 0 | M9: 0 | N9: 5280000000 | O9: DSE Official Daily Market Report | P9: 46265 | Q9: DSE-202608-10to13 | R9: {=IF($B9="","",IFERROR(IF(INDEX('Data Quality'!$U$4:$U$503,ROW()-3)=0,"PENDING",INDEX('Data Quality'!$U$4:$U$503,ROW()-3)),"PENDING"))} -> WARNING | S9: =IF($B9="","",IF(N($M9)>0,$L9/$M9,"")) | T9: =IF($B9="","",$L9*$E9) -> 0 | U9: =IF($B9="","",$M9*$E9) -> 0 | V9: =IF($B9="","",IF(N($N9)>0,$T9/$N9,"")) -> 0 | W9: =IF($B9="","",IF(N($N9)>0,$U9/$N9,"")) -> 0 | X9: =IF($B9="","",IF(N($J9)>0,$K9/$J9,"")) | Y9: =IF($B9="","",IF(N($J9)>0,$I9/$J9,"")) | Z9: =IF($B9="","",IF($AK9<=Settings!$C$21,"",IFERROR(AVERAGEIFS($S$4:$S$503,$B$4:$B$503,$B9,$AK$4:$AK$503,">="&$AK9-Settings!$C$21,$AK$4:$AK$503,"<="&$AK9-1),""))) | AA9: =IF(OR($S9="",$Z9="",N($Z9)=0),"",$S9/$Z9-1) | AB9: =IF($B9="","",IF($AK9<=Settings!$C$22,"",IFERROR(AVERAGEIFS($K$4:$K$503,$B$4:$B$503,$B9,$AK$4:$AK$503,">="&$AK9-Settings!$C$22,$AK$4:$AK$503,"<="&$AK9-1),""))) | AC9: =IF(OR($AB9="",N($AB9)=0),"",$K9/$AB9) | AD9: =IF($B9="","",IF($AK9<=Settings!$C$23,"",IFERROR($E9/SUMIFS($E$4:$E$503,$B$4:$B$503,$B9,$AK$4:$AK$503,$AK9-Settings!$C$23)-1,""))) | AE9: =IF($B9="","",IF($AK9<=Settings!$C$22,"",IFERROR($E9/SUMIFS($E$4:$E$503,$B$4:$B$503,$B9,$AK$4:$AK$503,$AK9-Settings!$C$22)-1,""))) | AF9: =IF($B9="","",IF(N($E9)>0,($F9-$G9)/$E9,"")) -> 0 | AG9: =IF($B9="","",ROUND((MIN(100,100*N($I9)/Settings!$C$27)+MIN(100,100*N($K9)/Settings!$C$28)+MIN(100,100*N($J9)/Settings!$C$29))/3,1)) -> 0 | AH9: =IF($B9="","",IF(SUM(Settings!$C$32:$C$37)=0,"",ROUND((Settings!$C$32*$AO9+Settings!$C$33*$AP9+Settings!$C$34*$AQ9+Settings!$C$35*$AR9+Settings!$C$36*$AS9+Settings!$C$37*$AT9)/SUM(Settings!$C$32:$C$37),1))) -> 50 | AI9: =IF($B9="","",MAX(0,100-IF(N($N9)>0,0,20)-IF(AND(N($L9)=0,N($M9)=0),15,0)-IF(N($J9)>0,0,10)-IF(N($K9)>0,0,10)-IF($Z9<>"",0,15)-IF($AB9<>"",0,10)-IF($R9="ERROR",20,IF($R9="WARNING",10,0)))) -> 30 | AJ9: =IF($AH9="","",IF($AH9<Settings!$C$46,"Extreme Sell Pressure",IF($AH9<Settings!$C$47,"Sell Pressure",IF($AH9<=Settings!$C$48,"Neutral",IF($AH9<=Settings!$C$49,"Buy Pressure","Extreme Buy Pressure"))))) -> Neutral | AK9: =IF($B9="","",COUNTIFS($B$4:$B$503,$B9,$A$4:$A$503,"<="&$A9)) -> 1 | AL9: =IF($A9="","",YEAR($A9)) -> 2026 | AM9: =IF($A9="","",_xlfn.ISOWEEKNUM($A9)) -> 33 | AN9: =IF($A9="","",MONTH($A9)) -> 8 | AO9: =IF($B9="","",IF(AND(N($L9)=0,N($M9)=0),50,IF(N($M9)=0,100,IF(N($L9)=0,0,MEDIAN(0,100,50+50*LN($S9)/LN(Settings!$C$40)))))) -> 50 | AP9: =IF($AA9="",50,MEDIAN(0,100,50+$AA9*100*Settings!$C$41)) -> 50 | AQ9: =IF($H9="",50,MEDIAN(0,100,50+$H9*100*Settings!$C$42)) -> 50 | AR9: =IF(OR($AC9="",$H9=""),50,MEDIAN(0,100,50+SIGN($H9)*50*MEDIAN(0,1,($AC9-1)/Settings!$C$43))) -> 50 | AS9: =IF(OR($V9="",$W9=""),50,MEDIAN(0,100,50+50*($V9-$W9)/Settings!$C$44)) -> 50 | AT9: =IF($AO9="",50,50+(N($AG9)/100)*($AO9-50)) -> 50 | AU9: =IF($B9="","",$B9&"|"&TEXT($A9,"yyyy-mm-dd")) -> JATU|2026-08-10 | AV9: =IF($A9="","",IF(COUNTIFS($A$4:$A9,$A9)=1,1,0)) -> 0
A10: 46244 | B10: JHL | C10: 8650 | E10: 8650 | H10: =IF($B10="","",IFERROR($E10/$D10-1,"")) | I10: 0 | J10: 0 | K10: 0 | L10: 0 | M10: 0 | N10: 626890000000 | O10: DSE Official Daily Market Report | P10: 46265 | Q10: DSE-202608-10to13 | R10: {=IF($B10="","",IFERROR(IF(INDEX('Data Quality'!$U$4:$U$503,ROW()-3)=0,"PENDING",INDEX('Data Quality'!$U$4:$U$503,ROW()-3)),"PENDING"))} -> WARNING | S10: =IF($B10="","",IF(N($M10)>0,$L10/$M10,"")) | T10: =IF($B10="","",$L10*$E10) -> 0 | U10: =IF($B10="","",$M10*$E10) -> 0 | V10: =IF($B10="","",IF(N($N10)>0,$T10/$N10,"")) -> 0 | W10: =IF($B10="","",IF(N($N10)>0,$U10/$N10,"")) -> 0 | X10: =IF($B10="","",IF(N($J10)>0,$K10/$J10,"")) | Y10: =IF($B10="","",IF(N($J10)>0,$I10/$J10,"")) | Z10: =IF($B10="","",IF($AK10<=Settings!$C$21,"",IFERROR(AVERAGEIFS($S$4:$S$503,$B$4:$B$503,$B10,$AK$4:$AK$503,">="&$AK10-Settings!$C$21,$AK$4:$AK$503,"<="&$AK10-1),""))) | AA10: =IF(OR($S10="",$Z10="",N($Z10)=0),"",$S10/$Z10-1) | AB10: =IF($B10="","",IF($AK10<=Settings!$C$22,"",IFERROR(AVERAGEIFS($K$4:$K$503,$B$4:$B$503,$B10,$AK$4:$AK$503,">="&$AK10-Settings!$C$22,$AK$4:$AK$503,"<="&$AK10-1),""))) | AC10: =IF(OR($AB10="",N($AB10)=0),"",$K10/$AB10) | AD10: =IF($B10="","",IF($AK10<=Settings!$C$23,"",IFERROR($E10/SUMIFS($E$4:$E$503,$B$4:$B$503,$B10,$AK$4:$AK$503,$AK10-Settings!$C$23)-1,""))) | AE10: =IF($B10="","",IF($AK10<=Settings!$C$22,"",IFERROR($E10/SUMIFS($E$4:$E$503,$B$4:$B$503,$B10,$AK$4:$AK$503,$AK10-Settings!$C$22)-1,""))) | AF10: =IF($B10="","",IF(N($E10)>0,($F10-$G10)/$E10,"")) -> 0 | AG10: =IF($B10="","",ROUND((MIN(100,100*N($I10)/Settings!$C$27)+MIN(100,100*N($K10)/Settings!$C$28)+MIN(100,100*N($J10)/Settings!$C$29))/3,1)) -> 0 | AH10: =IF($B10="","",IF(SUM(Settings!$C$32:$C$37)=0,"",ROUND((Settings!$C$32*$AO10+Settings!$C$33*$AP10+Settings!$C$34*$AQ10+Settings!$C$35*$AR10+Settings!$C$36*$AS10+Settings!$C$37*$AT10)/SUM(Settings!$C$32:$C$37),1))) -> 50 | AI10: =IF($B10="","",MAX(0,100-IF(N($N10)>0,0,20)-IF(AND(N($L10)=0,N($M10)=0),15,0)-IF(N($J10)>0,0,10)-IF(N($K10)>0,0,10)-IF($Z10<>"",0,15)-IF($AB10<>"",0,10)-IF($R10="ERROR",20,IF($R10="WARNING",10,0)))) -> 30 | AJ10: =IF($AH10="","",IF($AH10<Settings!$C$46,"Extreme Sell Pressure",IF($AH10<Settings!$C$47,"Sell Pressure",IF($AH10<=Settings!$C$48,"Neutral",IF($AH10<=Settings!$C$49,"Buy Pressure","Extreme Buy Pressure"))))) -> Neutral | AK10: =IF($B10="","",COUNTIFS($B$4:$B$503,$B10,$A$4:$A$503,"<="&$A10)) -> 1 | AL10: =IF($A10="","",YEAR($A10)) -> 2026 | AM10: =IF($A10="","",_xlfn.ISOWEEKNUM($A10)) -> 33 | AN10: =IF($A10="","",MONTH($A10)) -> 8 | AO10: =IF($B10="","",IF(AND(N($L10)=0,N($M10)=0),50,IF(N($M10)=0,100,IF(N($L10)=0,0,MEDIAN(0,100,50+50*LN($S10)/LN(Settings!$C$40)))))) -> 50 | AP10: =IF($AA10="",50,MEDIAN(0,100,50+$AA10*100*Settings!$C$41)) -> 50 | AQ10: =IF($H10="",50,MEDIAN(0,100,50+$H10*100*Settings!$C$42)) -> 50 | AR10: =IF(OR($AC10="",$H10=""),50,MEDIAN(0,100,50+SIGN($H10)*50*MEDIAN(0,1,($AC10-1)/Settings!$C$43))) -> 50 | AS10: =IF(OR($V10="",$W10=""),50,MEDIAN(0,100,50+50*($V10-$W10)/Settings!$C$44)) -> 50 | AT10: =IF($AO10="",50,50+(N($AG10)/100)*($AO10-50)) -> 50 | AU10: =IF($B10="","",$B10&"|"&TEXT($A10,"yyyy-mm-dd")) -> JHL|2026-08-10 | AV10: =IF($A10="","",IF(COUNTIFS($A$4:$A10,$A10)=1,1,0)) -> 0
A11: 46244 | B11: KA | C11: 110 | E11: 110 | H11: =IF($B11="","",IFERROR($E11/$D11-1,"")) | I11: 0 | J11: 0 | K11: 0 | L11: 230 | M11: 0 | N11: 624960000000 | O11: DSE Official Daily Market Report | P11: 46265 | Q11: DSE-202608-10to13 | R11: {=IF($B11="","",IFERROR(IF(INDEX('Data Quality'!$U$4:$U$503,ROW()-3)=0,"PENDING",INDEX('Data Quality'!$U$4:$U$503,ROW()-3)),"PENDING"))} -> PASS | S11: =IF($B11="","",IF(N($M11)>0,$L11/$M11,"")) | T11: =IF($B11="","",$L11*$E11) -> 25300 | U11: =IF($B11="","",$M11*$E11) -> 0 | V11: =IF($B11="","",IF(N($N11)>0,$T11/$N11,"")) -> 4.0482591e-08 | W11: =IF($B11="","",IF(N($N11)>0,$U11/$N11,"")) -> 0 | X11: =IF($B11="","",IF(N($J11)>0,$K11/$J11,"")) | Y11: =IF($B11="","",IF(N($J11)>0,$I11/$J11,"")) | Z11: =IF($B11="","",IF($AK11<=Settings!$C$21,"",IFERROR(AVERAGEIFS($S$4:$S$503,$B$4:$B$503,$B11,$AK$4:$AK$503,">="&$AK11-Settings!$C$21,$AK$4:$AK$503,"<="&$AK11-1),""))) | AA11: =IF(OR($S11="",$Z11="",N($Z11)=0),"",$S11/$Z11-1) | AB11: =IF($B11="","",IF($AK11<=Settings!$C$22,"",IFERROR(AVERAGEIFS($K$4:$K$503,$B$4:$B$503,$B11,$AK$4:$AK$503,">="&$AK11-Settings!$C$22,$AK$4:$AK$503,"<="&$AK11-1),""))) | AC11: =IF(OR($AB11="",N($AB11)=0),"",$K11/$AB11) | AD11: =IF($B11="","",IF($AK11<=Settings!$C$23,"",IFERROR($E11/SUMIFS($E$4:$E$503,$B$4:$B$503,$B11,$AK$4:$AK$503,$AK11-Settings!$C$23)-1,""))) | AE11: =IF($B11="","",IF($AK11<=Settings!$C$22,"",IFERROR($E11/SUMIFS($E$4:$E$503,$B$4:$B$503,$B11,$AK$4:$AK$503,$AK11-Settings!$C$22)-1,""))) | AF11: =IF($B11="","",IF(N($E11)>0,($F11-$G11)/$E11,"")) -> 0 | AG11: =IF($B11="","",ROUND((MIN(100,100*N($I11)/Settings!$C$27)+MIN(100,100*N($K11)/Settings!$C$28)+MIN(100,100*N($J11)/Settings!$C$29))/3,1)) -> 0 | AH11: =IF($B11="","",IF(SUM(Settings!$C$32:$C$37)=0,"",ROUND((Settings!$C$32*$AO11+Settings!$C$33*$AP11+Settings!$C$34*$AQ11+Settings!$C$35*$AR11+Settings!$C$36*$AS11+Settings!$C$37*$AT11)/SUM(Settings!$C$32:$C$37),1))) -> 65 | AI11: =IF($B11="","",MAX(0,100-IF(N($N11)>0,0,20)-IF(AND(N($L11)=0,N($M11)=0),15,0)-IF(N($J11)>0,0,10)-IF(N($K11)>0,0,10)-IF($Z11<>"",0,15)-IF($AB11<>"",0,10)-IF($R11="ERROR",20,IF($R11="WARNING",10,0)))) -> 55 | AJ11: =IF($AH11="","",IF($AH11<Settings!$C$46,"Extreme Sell Pressure",IF($AH11<Settings!$C$47,"Sell Pressure",IF($AH11<=Settings!$C$48,"Neutral",IF($AH11<=Settings!$C$49,"Buy Pressure","Extreme Buy Pressure"))))) -> Buy Pressure | AK11: =IF($B11="","",COUNTIFS($B$4:$B$503,$B11,$A$4:$A$503,"<="&$A11)) -> 1 | AL11: =IF($A11="","",YEAR($A11)) -> 2026 | AM11: =IF($A11="","",_xlfn.ISOWEEKNUM($A11)) -> 33 | AN11: =IF($A11="","",MONTH($A11)) -> 8 | AO11: =IF($B11="","",IF(AND(N($L11)=0,N($M11)=0),50,IF(N($M11)=0,100,IF(N($L11)=0,0,MEDIAN(0,100,50+50*LN($S11)/LN(Settings!$C$40)))))) -> 100 | AP11: =IF($AA11="",50,MEDIAN(0,100,50+$AA11*100*Settings!$C$41)) -> 50 | AQ11: =IF($H11="",50,MEDIAN(0,100,50+$H11*100*Settings!$C$42)) -> 50 | AR11: =IF(OR($AC11="",$H11=""),50,MEDIAN(0,100,50+SIGN($H11)*50*MEDIAN(0,1,($AC11-1)/Settings!$C$43))) -> 50 | AS11: =IF(OR($V11="",$W11=""),50,MEDIAN(0,100,50+50*($V11-$W11)/Settings!$C$44)) -> 50.004048 | AT11: =IF($AO11="",50,50+(N($AG11)/100)*($AO11-50)) -> 50 | AU11: =IF($B11="","",$B11&"|"&TEXT($A11,"yyyy-mm-dd")) -> KA|2026-08-10 | AV11: =IF($A11="","",IF(COUNTIFS($A$4:$A11,$A11)=1,1,0)) -> 0
A12: 46244 | B12: KCB | C12: 1890 | E12: 1900 | F12: 1900 | G12: 1880 | H12: =IF($B12="","",IFERROR($E12/$D12-1,"")) | I12: 10287840 | J12: 53 | K12: 5425 | L12: 10141 | M12: 23591 | N12: 5643650000000 | O12: DSE Official Daily Market Report | P12: 46265 | Q12: DSE-202608-10to13 | R12: {=IF($B12="","",IFERROR(IF(INDEX('Data Quality'!$U$4:$U$503,ROW()-3)=0,"PENDING",INDEX('Data Quality'!$U$4:$U$503,ROW()-3)),"PENDING"))} -> PASS | S12: =IF($B12="","",IF(N($M12)>0,$L12/$M12,"")) -> 0.42986732 | T12: =IF($B12="","",$L12*$E12) -> 19267900 | U12: =IF($B12="","",$M12*$E12) -> 44822900 | V12: =IF($B12="","",IF(N($N12)>0,$T12/$N12,"")) -> 3.4140849e-06 | W12: =IF($B12="","",IF(N($N12)>0,$U12/$N12,"")) -> 7.9421828e-06 | X12: =IF($B12="","",IF(N($J12)>0,$K12/$J12,"")) -> 102.35849 | Y12: =IF($B12="","",IF(N($J12)>0,$I12/$J12,"")) -> 194110.19 | Z12: =IF($B12="","",IF($AK12<=Settings!$C$21,"",IFERROR(AVERAGEIFS($S$4:$S$503,$B$4:$B$503,$B12,$AK$4:$AK$503,">="&$AK12-Settings!$C$21,$AK$4:$AK$503,"<="&$AK12-1),""))) | AA12: =IF(OR($S12="",$Z12="",N($Z12)=0),"",$S12/$Z12-1) | AB12: =IF($B12="","",IF($AK12<=Settings!$C$22,"",IFERROR(AVERAGEIFS($K$4:$K$503,$B$4:$B$503,$B12,$AK$4:$AK$503,">="&$AK12-Settings!$C$22,$AK$4:$AK$503,"<="&$AK12-1),""))) | AC12: =IF(OR($AB12="",N($AB12)=0),"",$K12/$AB12) | AD12: =IF($B12="","",IF($AK12<=Settings!$C$23,"",IFERROR($E12/SUMIFS($E$4:$E$503,$B$4:$B$503,$B12,$AK$4:$AK$503,$AK12-Settings!$C$23)-1,""))) | AE12: =IF($B12="","",IF($AK12<=Settings!$C$22,"",IFERROR($E12/SUMIFS($E$4:$E$503,$B$4:$B$503,$B12,$AK$4:$AK$503,$AK12-Settings!$C$22)-1,""))) | AF12: =IF($B12="","",IF(N($E12)>0,($F12-$G12)/$E12,"")) -> 0.010526316 | AG12: =IF($B12="","",ROUND((MIN(100,100*N($I12)/Settings!$C$27)+MIN(100,100*N($K12)/Settings!$C$28)+MIN(100,100*N($J12)/Settings!$C$29))/3,1)) -> 18.4 | AH12: =IF($B12="","",IF(SUM(Settings!$C$32:$C$37)=0,"",ROUND((Settings!$C$32*$AO12+Settings!$C$33*$AP12+Settings!$C$34*$AQ12+Settings!$C$35*$AR12+Settings!$C$36*$AS12+Settings!$C$37*$AT12)/SUM(Settings!$C$32:$C$37),1))) -> 40.3 | AI12: =IF($B12="","",MAX(0,100-IF(N($N12)>0,0,20)-IF(AND(N($L12)=0,N($M12)=0),15,0)-IF(N($J12)>0,0,10)-IF(N($K12)>0,0,10)-IF($Z12<>"",0,15)-IF($AB12<>"",0,10)-IF($R12="ERROR",20,IF($R12="WARNING",10,0)))) -> 75 | AJ12: =IF($AH12="","",IF($AH12<Settings!$C$46,"Extreme Sell Pressure",IF($AH12<Settings!$C$47,"Sell Pressure",IF($AH12<=Settings!$C$48,"Neutral",IF($AH12<=Settings!$C$49,"Buy Pressure","Extreme Buy Pressure"))))) -> Neutral | AK12: =IF($B12="","",COUNTIFS($B$4:$B$503,$B12,$A$4:$A$503,"<="&$A12)) -> 1 | AL12: =IF($A12="","",YEAR($A12)) -> 2026 | AM12: =IF($A12="","",_xlfn.ISOWEEKNUM($A12)) -> 33 | AN12: =IF($A12="","",MONTH($A12)) -> 8 | AO12: =IF($B12="","",IF(AND(N($L12)=0,N($M12)=0),50,IF(N($M12)=0,100,IF(N($L12)=0,0,MEDIAN(0,100,50+50*LN($S12)/LN(Settings!$C$40)))))) -> 19.549084 | AP12: =IF($AA12="",50,MEDIAN(0,100,50+$AA12*100*Settings!$C$41)) -> 50 | AQ12: =IF($H12="",50,MEDIAN(0,100,50+$H12*100*Settings!$C$42)) -> 50 | AR12: =IF(OR($AC12="",$H12=""),50,MEDIAN(0,100,50+SIGN($H12)*50*MEDIAN(0,1,($AC12-1)/Settings!$C$43))) -> 50 | AS12: =IF(OR($V12="",$W12=""),50,MEDIAN(0,100,50+50*($V12-$W12)/Settings!$C$44)) -> 49.54719 | AT12: =IF($AO12="",50,50+(N($AG12)/100)*($AO12-50)) -> 44.397031 | AU12: =IF($B12="","",$B12&"|"&TEXT($A12,"yyyy-mm-dd")) -> KCB|2026-08-10 | AV12: =IF($A12="","",IF(COUNTIFS($A$4:$A12,$A12)=1,1,0)) -> 0
A13: 46244 | B13: MBP | C13: 1600 | E13: 1660 | F13: 1790 | G13: 1600 | H13: =IF($B13="","",IFERROR($E13/$D13-1,"")) | I13: 2049600 | J13: 13 | K13: 1232 | L13: 4005 | M13: 23587 | N13: 49780000000 | O13: DSE Official Daily Market Report | P13: 46265 | Q13: DSE-202608-10to13 | R13: {=IF($B13="","",IFERROR(IF(INDEX('Data Quality'!$U$4:$U$503,ROW()-3)=0,"PENDING",INDEX('Data Quality'!$U$4:$U$503,ROW()-3)),"PENDING"))} -> PASS | S13: =IF($B13="","",IF(N($M13)>0,$L13/$M13,"")) -> 0.16979692 | T13: =IF($B13="","",$L13*$E13) -> 6648300 | U13: =IF($B13="","",$M13*$E13) -> 39154420 | V13: =IF($B13="","",IF(N($N13)>0,$T13/$N13,"")) -> 0.00013355364 | W13: =IF($B13="","",IF(N($N13)>0,$U13/$N13,"")) -> 0.00078654922 | X13: =IF($B13="","",IF(N($J13)>0,$K13/$J13,"")) -> 94.769231 | Y13: =IF($B13="","",IF(N($J13)>0,$I13/$J13,"")) -> 157661.54 | Z13: =IF($B13="","",IF($AK13<=Settings!$C$21,"",IFERROR(AVERAGEIFS($S$4:$S$503,$B$4:$B$503,$B13,$AK$4:$AK$503,">="&$AK13-Settings!$C$21,$AK$4:$AK$503,"<="&$AK13-1),""))) | AA13: =IF(OR($S13="",$Z13="",N($Z13)=0),"",$S13/$Z13-1) | AB13: =IF($B13="","",IF($AK13<=Settings!$C$22,"",IFERROR(AVERAGEIFS($K$4:$K$503,$B$4:$B$503,$B13,$AK$4:$AK$503,">="&$AK13-Settings!$C$22,$AK$4:$AK$503,"<="&$AK13-1),""))) | AC13: =IF(OR($AB13="",N($AB13)=0),"",$K13/$AB13) | AD13: =IF($B13="","",IF($AK13<=Settings!$C$23,"",IFERROR($E13/SUMIFS($E$4:$E$503,$B$4:$B$503,$B13,$AK$4:$AK$503,$AK13-Settings!$C$23)-1,""))) | AE13: =IF($B13="","",IF($AK13<=Settings!$C$22,"",IFERROR($E13/SUMIFS($E$4:$E$503,$B$4:$B$503,$B13,$AK$4:$AK$503,$AK13-Settings!$C$22)-1,""))) | AF13: =IF($B13="","",IF(N($E13)>0,($F13-$G13)/$E13,"")) -> 0.11445783 | AG13: =IF($B13="","",ROUND((MIN(100,100*N($I13)/Settings!$C$27)+MIN(100,100*N($K13)/Settings!$C$28)+MIN(100,100*N($J13)/Settings!$C$29))/3,1)) -> 4.5 | AH13: =IF($B13="","",IF(SUM(Settings!$C$32:$C$37)=0,"",ROUND((Settings!$C$32*$AO13+Settings!$C$33*$AP13+Settings!$C$34*$AQ13+Settings!$C$35*$AR13+Settings!$C$36*$AS13+Settings!$C$37*$AT13)/SUM(Settings!$C$32:$C$37),1))) -> 29.8 | AI13: =IF($B13="","",MAX(0,100-IF(N($N13)>0,0,20)-IF(AND(N($L13)=0,N($M13)=0),15,0)-IF(N($J13)>0,0,10)-IF(N($K13)>0,0,10)-IF($Z13<>"",0,15)-IF($AB13<>"",0,10)-IF($R13="ERROR",20,IF($R13="WARNING",10,0)))) -> 75 | AJ13: =IF($AH13="","",IF($AH13<Settings!$C$46,"Extreme Sell Pressure",IF($AH13<Settings!$C$47,"Sell Pressure",IF($AH13<=Settings!$C$48,"Neutral",IF($AH13<=Settings!$C$49,"Buy Pressure","Extreme Buy Pressure"))))) -> Sell Pressure | AK13: =IF($B13="","",COUNTIFS($B$4:$B$503,$B13,$A$4:$A$503,"<="&$A13)) -> 1 | AL13: =IF($A13="","",YEAR($A13)) -> 2026 | AM13: =IF($A13="","",_xlfn.ISOWEEKNUM($A13)) -> 33 | AN13: =IF($A13="","",MONTH($A13)) -> 8 | AO13: =IF($B13="","",IF(AND(N($L13)=0,N($M13)=0),50,IF(N($M13)=0,100,IF(N($L13)=0,0,MEDIAN(0,100,50+50*LN($S13)/LN(Settings!$C$40)))))) -> 0 | AP13: =IF($AA13="",50,MEDIAN(0,100,50+$AA13*100*Settings!$C$41)) -> 50 | AQ13: =IF($H13="",50,MEDIAN(0,100,50+$H13*100*Settings!$C$42)) -> 50 | AR13: =IF(OR($AC13="",$H13=""),50,MEDIAN(0,100,50+SIGN($H13)*50*MEDIAN(0,1,($AC13-1)/Settings!$C$43))) -> 50 | AS13: =IF(OR($V13="",$W13=""),50,MEDIAN(0,100,50+50*($V13-$W13)/Settings!$C$44)) -> 0 | AT13: =IF($AO13="",50,50+(N($AG13)/100)*($AO13-50)) -> 47.75 | AU13: =IF($B13="","",$B13&"|"&TEXT($A13,"yyyy-mm-dd")) -> MBP|2026-08-10 | AV13: =IF($A13="","",IF(COUNTIFS($A$4:$A13,$A13)=1,1,0)) -> 0
